Workbook

Sheet Appendix_BC-Networks
A1: Blockchain Network
A2: Bitcoin | G2: Ethereum | M2: Cardano | S2: Solana | Y2: Ripple
A3: Source: Bitnodes (2025). Bitnodes estimates the relative size of the Bitcoin peer-to-peer network by finding all of its reachable nodes. [Access: 07.11.2025]; [Online-available: https://bitnodes.io/nodes/all/countries/1d/] | B3: Nr. | C3: Country | D3: Active Nodes per Country | G3: Source: Ethereum Mainnet Statistics (2025). Consensus Layer Countries. [Access: 07.11.2025]; [Online-available: https://www.ethernodes.org/countries] | H3: Nr. | I3: Country | J3: Active Nodes per Country | M3: Source: Cexplorer.io (2025). Relays Dominance by country. [Access: 10.11.2025]; [Online-available: https://cexplorer.io/relays] | N3: Nr. | O3: Country | P3: Active Nodes per Country | S3: Source: Solana Compass (2025). Solana's Decentralization In Numbers. [Access: 10.11.2025]; [Online-available: https://solanacompass.com/statistics/decentralization] | T3: Nr. | U3: Country | V3: Active Nodes per Country | Y3: Source: Bithomp (2025). 889 XRPL nodes. Explore the list of XRPL nodes. View up-to-date statistics on node versions and countries (updated a few seconds ago). [Access: 10.11.2025]; [Online-available: https://bithomp.com/en/nodes] | Z3: Nr. | AA3: Country | AB3: Active Nodes per Country
D4: Absolute | E4: in % | J4: Absolute | K4: in % | P4: Absolute | Q4: in % | V4: Absolute | W4: in % | AB4: Absolute | AC4: in %
B5: 1 | C5: USA | D5: 15752 | E5: =D5/$D$31 -> 0.23099484 | H5: 1 | I5: USA | J5: 2858 | K5: =$J5/$J$31 -> 0.31615044 | N5: 1 | O5: Germany | P5: 787 | Q5: =$P5/$P$58 -> 0.27440725 | T5: 1 | U5: USA | V5: 1787 | W5: =$V5/$V$31 -> 0.30547009 | Z5: 1 | AA5: USA | AB5: 194 | AC5: =$AB5/$AB$31 -> 0.21822272
B6: 2 | C6: Germany | D6: 6813 | E6: =D6/$D$31 -> 0.09990908 | H6: 2 | I6: Germany | J6: 1353 | K6: =$J6/$J$31 -> 0.14966814 | N6: 2 | O6: USA | P6: 743 | Q6: =$P6/$P$58 -> 0.25906555 | T6: 2 | U6: Germany | V6: 1170 | W6: =$V6/$V$31 -> 0.2 | Z6: 2 | AA6: Germany | AB6: 105 | AC6: =$AB6/$AB$31 -> 0.11811024
B7: 3 | C7: France | D7: 2333 | E7: =D7/$D$31 -> 0.034212224 | H7: 3 | I7: Finland | J7: 552 | K7: =$J7/$J$31 -> 0.061061947 | N7: 3 | O7: United Kingdom | P7: 174 | Q7: =$P7/$P$58 -> 0.060669456 | T7: 3 | U7: Netherlands | V7: 708 | W7: =$V7/$V$31 -> 0.12102564 | Z7: 3 | AA7: Finland | AB7: 63 | AC7: =$AB7/$AB$31 -> 0.070866142
B8: 4 | C8: Canada | D8: 2271 | E8: =D8/$D$31 -> 0.033303027 | H8: 4 | I8: France | J8: 531 | K8: =$J8/$J$31 -> 0.058738938 | N8: 4 | O8: Netherlands | P8: 142 | Q8: =$P8/$P$58 -> 0.049511855 | T8: 4 | U8: France | V8: 341 | W8: =$V8/$V$31 -> 0.058290598 | Z8: 4 | AA8: Japan | AB8: 47 | AC8: =$AB8/$AB$31 -> 0.052868391
B9: 5 | C9: United Kingdom | D9: 1771 | E9: =D9/$D$31 -> 0.025970788 | H9: 5 | I9: United Kingdom | J9: 378 | K9: =$J9/$J$31 -> 0.041814159 | N9: 5 | O9: France | P9: 113 | Q9: =$P9/$P$58 -> 0.039400279 | T9: 5 | U9: Canada | V9: 338 | W9: =$V9/$V$31 -> 0.057777778 | Z9: 5 | AA9: Singapore | AB9: 41 | AC9: =$AB9/$AB$31 -> 0.046119235
B10: 6 | C10: Netherlands | D10: 1710 | E10: =D10/$D$31 -> 0.025076255 | H10: 6 | I10: Singapore | J10: 349 | K10: =$J10/$J$31 -> 0.038606195 | N10: 6 | O10: Japan | P10: 131 | Q10: =$P10/$P$58 -> 0.04567643 | T10: 6 | U10: Japan | V10: 312 | W10: =$V10/$V$31 -> 0.053333333 | Z10: 6 | AA10: Netherlands | AB10: 34 | AC10: =$AB10/$AB$31 -> 0.038245219
B11: 7 | C11: China | D11: 1451 | E11: =D11/$D$31 -> 0.021278156 | H11: 7 | I11: Canada | J11: 315 | K11: =$J11/$J$31 -> 0.034845133 | N11: 7 | O11: Canada | P11: 154 | Q11: =$P11/$P$58 -> 0.053695955 | T11: 7 | U11: Singapore | V11: 239 | W11: =$V11/$V$31 -> 0.040854701 | Z11: 7 | AA11: France | AB11: 32 | AC11: =$AB11/$AB$31 -> 0.035995501
B12: 8 | C12: Australia | D12: 1357 | E12: =D12/$D$31 -> 0.019899695 | H12: 8 | I12: Netherlands | J12: 257 | K12: =$J12/$J$31 -> 0.028429204 | N12: 8 | O12: Sweden | P12: 38 | Q12: =$P12/$P$58 -> 0.013249651 | T12: 8 | U12: United Kingdom | V12: 238 | W12: =$V12/$V$31 -> 0.040683761 | Z12: 8 | AA12: South Korea | AB12: 25 | AC12: =$AB12/$AB$31 -> 0.028121485
B13: 9 | C13: Switzerland | D13: 1205 | E13: =D13/$D$31 -> 0.017670695 | H13: 9 | I13: Japan | J13: 254 | K13: =$J13/$J$31 -> 0.028097345 | N13: 9 | O13: Finland | P13: 101 | Q13: =$P13/$P$58 -> 0.035216179 | T13: 9 | U13: Lithunia | V13: 66 | W13: =$V13/$V$31 -> 0.011282051 | Z13: 9 | AA13: Ireland | AB13: 25 | AC13: =$AB13/$AB$31 -> 0.028121485
B14: 10 | C14: Spain | D14: 1145 | E14: =D14/$D$31 -> 0.016790826 | H14: 10 | I14: South Korea | J14: 213 | K14: =$J14/$J$31 -> 0.023561947 | N14: 10 | O14: Ireland | P14: 37 | Q14: =$P14/$P$58 -> 0.012900976 | T14: 10 | U14: Ireland | V14: 65 | W14: =$V14/$V$31 -> 0.011111111 | Z14: 10 | AA14: United Kingdom | AB14: 23 | AC14: =$AB14/$AB$31 -> 0.025871766
B15: 11 | C15: Italy | D15: 1099 | E15: =D15/$D$31 -> 0.01611626 | H15: 11 | I15: Ireland | J15: 191 | K15: =$J15/$J$31 -> 0.021128319 | N15: 11 | O15: South Korea | P15: 53 | Q15: =$P15/$P$58 -> 0.018479777 | T15: 11 | U15: Russia | V15: 43 | W15: =$V15/$V$31 -> 0.0073504274 | Z15: 11 | AA15: Canada | AB15: 20 | AC15: =$AB15/$AB$31 -> 0.022497188
B16: 12 | C16: Russia | D16: 1090 | E16: =D16/$D$31 -> 0.01598428 | H16: 12 | I16: Austria | J16: 174 | K16: =$J16/$J$31 -> 0.019247788 | N16: 12 | O16: Australia | P16: 50 | Q16: =$P16/$P$58 -> 0.017433752 | T16: 12 | U16: Norway | V16: 36 | W16: =$V16/$V$31 -> 0.0061538462 | Z16: 12 | AA16: Estonia | AB16: 11 | AC16: =$AB16/$AB$31 -> 0.012373453
... B29: 25 | C29: Mexico | D29: 336 | E29: =D29/$D$31 -> 0.0049272642 | H29: 25 | I29: india | J29: 33 | K29: =$J29/$J$31 -> 0.0036504425 | N29: 25 | O29: Estonia | P29: 7 | Q29: =$P29/$P$58 -> 0.0024407252 | T29: 25 | U29: Romania | V29: 12 | W29: =$V29/$V$31 -> 0.0020512821 | Z29: 25 | AA29: Latvia | AB29: 3 | AC29: =$AB29/$AB$31 -> 0.0033745782
C30: Other | D30: =D31-SUM(D5:D29) -> 22952 | E30: =D30/$D$31 -> 0.33657907 | I30: Other | J30: =J31-SUM(J5:J29) -> 723 | K30: =$J30/$J$31 -> 0.079977876 | N30: 26 | O30: Spain | P30: 14 | Q30: =$P30/$P$58 -> 0.0048814505 | U30: Other | V30: =$V$31-SUM(V5:V29) -> 245 | W30: =$V30/$V$31 -> 0.041880342 | AA30: Other | AB30: =$AB$31-SUM(AB5:AB29) -> 194 | AC30: =$AB30/$AB$31 -> 0.21822272
C31: Total | D31: 68192 | E31: =SUM(E5:E30) -> 1 | I31: Total | J31: 9040 | K31: =SUM(K5:K30) -> 1 | N31: 27 | O31: Lativia | P31: 3 | Q31: =$P31/$P$58 -> 0.0010460251 | U31: Total | V31: 5850 | W31: =SUM(W5:W30) -> 1 | AA31: Total | AB31: 889 | AC31: =SUM(AC5:AC30) -> 1
N32: 28 | O32: New Zealand | P32: 4 | Q32: =$P32/$P$58 -> 0.0013947001
N33: 29 | O33: Lithunia | P33: 2 | Q33: =$P33/$P$58 -> 0.00069735007
N34: 30 | O34: Italy | P34: 13 | Q34: =$P34/$P$58 -> 0.0045327755
N35: 31 | O35: Romania | P35: 5 | Q35: =$P35/$P$58 -> 0.0017433752
N36: 32 | O36: Chile | P36: 5 | Q36: =$P36/$P$58 -> 0.0017433752
N37: 33 | O37: Greece | P37: 4 | Q37: =$P37/$P$58 -> 0.0013947001
N38: 34 | O38: Indonesia | P38: 2 | Q38: =$P38/$P$58 -> 0.00069735007
N39: 35 | O39: Czech Republic | P39: 12 | Q39: =$P39/$P$58 -> 0.0041841004
N40: 36 | O40: Seychelles | P40: 1 | Q40: =$P40/$P$58 -> 0.00034867503
N41: 37 | O41: Thailand | P41: 3 | Q41: =$P41/$P$58 -> 0.0010460251
N42: 38 | O42: Taiwan | P42: 6 | Q42: =$P42/$P$58 -> 0.0020920502
N43: 39 | O43: Cyprus | P43: 3 | Q43: =$P43/$P$58 -> 0.0010460251
... N57: 53 | O57: New Caledonia | P57: 1 | Q57: =$P57/$P$58 -> 0.00034867503
O58: Total | P58: =SUM(P5:P57) -> 2868 | Q58: 1

Sheet Table1 - Literature
A1: No | B1: Authors | C1: Short Reference | D1: Publication Type | E1: Main Focus | F1: Quantitative Energy Data | G1: Qualitative Energy Assessment | H1: Relevance Category
A2: 1 | B2: Bachani & Bhattachariya | C2: Preferential DPoS (PDPoS) | D2: Journal article: doi.org/10.3390/sym15010004 | E2: Modified DPoS for scalability | F2: No | G2: Yes – efficiency arguments | H2: Algorithmic
A3: 2 | B3: Bada et al. | C3: Towards a Green Blockchain | D3: Review article: doi.org/10.1109/DCOSS52077.2021.00083 | E3: Overview of energy-efficient consensus | F3: No | G3: Yes | H3: Conceptual review
A4: 3 | B4: Bouraga | C4: Taxonomy of Blockchain Consensus Protocols | D4: Survey article: doi.org/10.1016/j.eswa.2020.114384 | E4: Classification of consensus mechanisms | F4: No | G4: Yes – efficiency traits | H4: Conceptual taxonomy
A5: 4 | B5: Kably et al. | C5: Lightweight DAG Blockchain for IoT | D5: Journal article: doi.org/10.32604/cmc.2022.020833 | E5: Low-power DAG consensus for constrained devices | F5: Partial | G5: Yes | H5: Application-oriented
A6: 5 | B6: Kohli et al. | C6: Energy Consumption and Carbon Footprints of Cryptocurrencies | D6: Journal article: doi.org/10.1016/j.dcan.2022.06.017 | E6: Energy & CO₂ footprint of major blockchains | F6: Yes | G6: Yes | H6: Core quantitative
A7: 6 | B7: Lamriji et al. | C7: Comparative Study of Consensus Algorithms | D7: Journal article: doi.org/10.1109/IRASET57153.2023.10153031 | E7: Performance, scalability, security comparison | F7: No | G7: Yes – qualitative energy implications | H7: Conceptual survey
A8: 7 | B8: Masood et al. (2018) | C8: Consensus Algorithms in DLT for Open Environment | D8: Journal article: doi.org/10.1109/CCAA.2018.8777695 | E8: Comparison of PoW, PoS, PBFT in open environments | F8: Partial | G8: Yes – discusses energy efficiency trends | H8: Conceptual + partial empirical
A9: 8 | B9: Nguyen et al. | C9: PoS Consensus Mechanisms for Future Networks | D9: Survey article: doi.org/10.1109/ACCESS.2019.2925010 | E9: Comprehensive PoS survey | F9: No | G9: Yes – energy efficiency narrative | H9: Conceptual survey
A10: 9 | B10: Platt et al. | C10: Energy Footprint Beyond PoW | D10: Journal article: doi.org/10.1109/QRS-C55045.2021.00168 | E10: Empirical comparison of PoW, PoS, PBFT, DAG | F10: Yes | G10: Yes | H10: Core quantitative
A11: 10 | B11: Rajan et al. | C11: Blockchain Framework for Big Data at the Edge | D11: Journal article: doi.org/10.1109/ICACITE57410.2023.10183224 | E11: Energy-aware blockchain design for edge computing | F11: Partial | G11: Yes | H11: Application-oriented
A12: 11 | B12: Roma & Anwar | C12: Energy Consumption of XRP Validator | D12: Technical report / Journal: doi.org/10.1109/ICBC48266.2020.9169427 | E12: Empirical XRP validator energy measurement | F12: Yes | G12: Yes | H12: Core quantitative
A13: 12 | B13: Sapra & Shaikh | C13: Impact of Bitcoin Mining on Energy Use | D13: Journal article: doi.org/10.1108/MF-03-2023-0179 | E13: Drivers of Bitcoin energy consumption | F13: Yes | G13: Yes | H13: Core quantitative
... A18: 17 | B18: Zhang et al. | C18: QPBFT Consensus Algorithm | D18: Journal article: doi.org/10.1109/TrustCom50675.2020.00132 | E18: PBFT variant improving efficiency & latency | F18: No | G18: Yes – energy reduction discussed | H18: Algorithmic

Sheet Table2 - Data sources
A1: No. | B1: Data source | C1: URL | D1: Access date | E1: Description / Data provided
A2: 1 | B2: Carbon Ratings Index (CCRI) | C2: https://indices.carbon-ratings.com/ | D2: 45697 | E2: Annual network energy consumption (kWh/a) and total CO₂e emissions for major blockchain networks
A3: 2 | B3: Electricity Maps ApS | C3: https://www.electricitymaps.com/ | D3: 45697 | E3: Country-level electricity mix and CO₂e intensity (gCO₂e/kWh) used for emissions calculations
A4: 3 | B4: Our World in Data (Oxford University) | C4: https://ourworldindata.org/ | D4: 45697 | E4: National CO₂ emission factors and energy mix statistics
A5: 4 | B5: Etherscan | C5: https://etherscan.io/ | D5: 45697 | E5: Ethereum transaction counts and network activity
A6: 5 | B6: Solscan | C6: https://solscan.io/ | D6: 45697 | E6: Solana transaction volume and network statistics
A7: 6 | B7: XRPScan | C7: https://xrpscan.com/ | D7: 45697 | E7: Ripple (XRP Ledger) transaction counts and validator metrics
A8: 7 | B8: IOTA Explorer | C8: https://explorer.iota.org/ | D8: 45697 | E8: IOTA network activity and transaction volume
A9: 8 | B9: BitInfoCharts | C9: https://bitinfocharts.com/ | D9: 45697 | E9: Bitcoin and Ethereum transaction fees, transaction counts
A10: 9 | B10: YCharts | C10: https://ycharts.com/ | D10: 45697 | E10: Average transaction fees for Bitcoin and Ethereum
A11: 10 | B11: The Block (Data) | C11: https://www.theblock.co/data | D11: 45697 | E11: Comparative on-chain metrics (BTC, ETH, SOL)
A12: 11 | B12: CoinCodex | C12: https://coincodex.com/ | D12: 45697 | E12: Gas fees, transaction costs, price-based conversions
A13: 12 | B13: Coinbase | C13: https://www.coinbase.com/ | D13: 45697 | E13: Cryptocurrency price data (USD conversions)
... A15: 14 | B15: IOTA Services | C15: https://www.iota-services.com/ | D15: 45697 | E15: Zero-fee and DAG architecture documentation

Sheet Table4 - Overview of systems
A1: Blockchain-System | B1: Annual network energy consumption (9.11.25) | C1: Total Transaction (Extrapolated from 09.11.2025) | D1: Total CO2e-Emissions per Network (9.11.2025) | E1: gCO2e-Emissions per Transaction (9.11.2025)
B2: [kWh/a] | C2: [tx] | D2: [t CO2e] | E2: [g CO2e/tx]
A3: Bitcoin | B3: =177.8*10^9 -> 177800000000 | C3: =365*466.206*1000 -> 170165190 | D3: =69.99*10^6 -> 69990000 | E3: =D3*10^6/C3 -> 411306.21
A4: Ethereum | B4: =4298.27*1000 -> 4298270 | C4: =365*1.4583*10^6 -> 532279500 | D4: 1313.39 | E4: =D4*10^6/C4 -> 2.4674818
A5: Cardano | B5: =436.9*1000 -> 436900 | C5: =77263*365 -> 28200995 | D5: 149.88 | E5: =D5*10^6/C5 -> 5.3147061
A6: Solana | B6: =16511.76*1000 -> 16511760 | C6: =365*250718529 -> 91512263085 | D6: 5075.04 | E6: =D6*10^6/C6 -> 0.055457485
A7: Ripple | B7: =471.77*1000 -> 471770 | C7: =365*1069624 -> 390412760 | D7: 194.18 | E7: =D7*10^6/C7 -> 0.49737104
A8: Iota | B8: =217.81*1000 -> 217810 | C8: =1.91*10^6*365 -> 697150000 | D8: 56.47 | E8: =D8*10^6/C8 -> 0.081001219
A12: Source Energy Consumption | B12: https://indices.carbon-ratings.com/?
A13: Source Emissions | B13: https://indices.carbon-ratings.com/?
A14: Sources for Transactions | B14: Bitcoin | C14: Bitcoin, Ethereum Transactions Chart
B15: Ethereum | C15: Ethereum Transactions Information | Etherscan
C16: Bitcoin, Ethereum Transactions Chart
B17: Cardano | C17: Cardano transactions per seconds (TPS) | Cardano Explorer
B18: Solana | C18: Solana Analytics | Solscan
B19: Ripple | C19: XRP Ledger Metrics | XRPSCAN
C20: XRP Transactions Chart
B21: Iota | C21: IOTA Explorer

Sheet Table5 - Calculated values
A1: Blockchain-System | B1: Energy Consumption per Transaction | C1: Number of Nodes for each Network | D1: Energy per Network Node per year | E1: Energy per Network Node per h | F1: Mean price per Transaction | J1: Price Calculation | K1: Bitcoin | L1: Sources | M1: Ethereum | N1: Sources | O1: Ripple | P1: Sources | Q1: Cardano | R1: Sources | S1: Solana | T1: Sources | U1: Iota | V1: Sources
B2: [kWh / tx] | C2: Numbers | D2: [kWh / Node / a] | E2: kWh/node/h | F2: [$ / Tx] | K2: 0.918 | L2: https://ycharts.com/indicators/bitcoin_average_transaction_fee? | M2: 0.358 | N2: https://ycharts.com/indicators/ethereum_average_transaction_fee? | O2: 0.0014 | P2: https://bitinfocharts.com/xrp/ | Q2: ADA | R2: https://gasfees.org/what-are-cardano-gas-fees/ | S2: 0.00025 | T2: b2binpay.com/en/news/top-12-cheapest-crypto-to-transfer-and-save-on-transaction-fees | U2: 0 | V2: https://letsexchange.io/blog/cryptocurrencies-with-the-lowest-transaction-fees/
A3: Bitcoin | B3: ='Table4 - Overview of systems'!B3/'Table4 - Overview of systems'!C3 -> 1044.867 | C3: 68192 | D3: ='Table4 - Overview of systems'!B3/'Table5 - Calculated values'!C3 -> 2607344 | E3: =D3/(365*24) -> 297.64201 | F3: =K6 -> 1.012 | K3: 0.84 | L3: https://www.theblock.co/data/on-chain-metrics/comparison-bitcoin-ethereum-solana/average-transaction-fee | M3: 0.81 | N3: https://www.theblock.co/data/on-chain-metrics/comparison-bitcoin-ethereum-solana/average-transaction-fee | O3: 0.0003 | P3: /b2binpay.com/en/news/top-12-cheapest-crypto-to-transfer-and-save-on-transaction-fees | Q3: 0.1641702 | R3: https://www.coinbase.com/en-de/converter/ada/usd | S3: 0.0028 | T3: https://coincodex.com/article/24933/solana-gas-fees/ | V3: https://www.iota-services.com/what-is-iota/
A4: Ethereum | B4: ='Table4 - Overview of systems'!B4/'Table4 - Overview of systems'!C4 -> 0.0080752124 | C4: 9040 | D4: ='Table4 - Overview of systems'!B4/'Table5 - Calculated values'!C4 -> 475.47235 | E4: =D4/(365*24) -> 0.054277665 | F4: =M6 -> 0.559 | K4: 0.91 | L4: https://bitinfocharts.com/bitcoin/ | M4: 0.538 | N4: https://bitinfocharts.com/comparison/transactionfees-btc-eth.html#3y | Q4: Price
A5: Cardano | B5: ='Table4 - Overview of systems'!B5/'Table4 - Overview of systems'!C5 -> 0.015492361 | C5: 2868 | D5: ='Table4 - Overview of systems'!B5/'Table5 - Calculated values'!C5 -> 152.33612 | E5: =D5/(365*24) -> 0.017389968 | F5: =Q6 -> 0.095218716 | K5: 1.38 | L5: https://coincodex.com/article/24933/solana-gas-fees/ | M5: 0.53 | N5: https://etherscan.io/txs | Q5: 0.58
A6: Solana | B6: ='Table4 - Overview of systems'!B6/'Table4 - Overview of systems'!C6 -> 0.00018043221 | C6: 5850 | D6: ='Table4 - Overview of systems'!B6/'Table5 - Calculated values'!C6 -> 2822.5231 | E6: =D6/(365*24) -> 0.32220583 | F6: =S6 -> 0.001525 | J6: Mean Value | K6: =AVERAGE(K2:K5) -> 1.012 | M6: =AVERAGE(M2:M5) -> 0.559 | O6: =AVERAGE(O2:O3) -> 0.00085 | Q6: =Q5*Q3 -> 0.095218716 | S6: =AVERAGE(S2:S3) -> 0.001525 | U6: 0
A7: Ripple | B7: ='Table4 - Overview of systems'!B7/'Table4 - Overview of systems'!C7 -> 0.0012083878 | C7: 889 | D7: ='Table4 - Overview of systems'!B7/'Table5 - Calculated values'!C7 -> 530.67492 | E7: =D7/(365*24) -> 0.060579328 | F7: =O6 -> 0.00085
A8: Iota | B8: ='Table4 - Overview of systems'!B8/'Table4 - Overview of systems'!C8 -> 0.00031242918 | C8: undefined | D8: undefined | E8: undefined | F8: 0
A45: Iota
A46: 0 | B46: https://letsexchange.io/blog/cryptocurrencies-with-the-lowest-transaction-fees/
B47: https://www.iota-services.com/what-is-iota/

Sheet Table6 - Emissions
A1: Country | C1: gCO2e/kWh | D1: Country | F1: gCO2e/kWh | G1: Country | I1: gCO2e/kWh
A2: IND | B2: India | C2: 774.59956 | D2: EST | E2: Estonia | F2: 433.8617 | G2: AUT | H2: Spain | I2: 160.03648 | K2: Sources = Average from | M2: Carbon Footprint Lrd
A3: POL | B3: Poland | C3: 698.98001 | D3: GER | E3: Germany | F3: 384.64973 | G3: CAN | H3: Canada | I3: 142.99995 | M3: *Our World in Data
A4: HGK | B4: Hong Kong | C4: 695.96903 | D4: USA | E4: USA | F4: 371.79463 | G4: FIN | H4: Finland | I4: 88.338273 | M4: ElecticityMaps
A5: CHN | B5: China | C5: 621.40188 | D5: ITA | E5: Italy | F5: 346.27211 | G5: BRA | H5: Brazil | I5: 80.782081
A6: AUS | B6: Australia | C6: 566.70679 | D6: IRL | E6: Ireland | F6: 338.04433 | G6: FRA | H6: France | I6: 57.184045
A7: SGP | B7: Singapore | C7: 486.83131 | D7: NLD | E7: Netherlands | F7: 313.00492 | G7: CHE | H7: Switzerland | I7: 43.228378
A8: JPN | B8: Japan | C8: 467.46655 | D8: GBR | E8: United Kingdom | F8: 221.80271 | G8: SWE | H8: Sweden | I8: 25.64434
A9: RUS | B9: Russia | C9: 448.47052 | D9: LTU | E9: Lithuania | F9: 169.75148 | G9: NOR | H9: Norway | I9: 22.945155
A10: KOR | B10: South Korea | C10: 439.51702 | D10: ESP | E10: Austria | F10: 165.778 | G10: *World Average | I10: 481

Sheet Table7 - Bitcoin
A2: Bitcoin | B2: Top 15 Country | D2: Nodes | F2: Average Emissions per Energy by Country | H2: Total network energy consumption (09.11.25) | K2: CO2e Emissions per transaction [kgCO2e/tx]
B3: [Distribution of Nodes] | D3: % | E3: Absolute | F3: [gCO2e / kWh] | H3: By Country [t] | I3: % | K3: Average for the network | L3: Factor > 1 = good to notarize; Factor < 1 = bad to notarize
B4: USA | C4: USA | D4: ='Appendix_BC-Networks'!E5 -> 0.23099484 | E4: ='Appendix_BC-Networks'!D5 -> 15752 | F4: ='Table6 - Emissions'!F4 -> 371.79463 | H4: =($E4*$F4*'Table5 - Calculated values'!$D$3)/10^6 -> 15269934 | I4: =$H4/$H$20 -> 0.21817307 | K4: =$H$20*1000/'Table4 - Overview of systems'!C3 -> 411.30621 | L4: =D4/I4 -> 1.0587688
B5: GER | C5: Germany | D5: ='Appendix_BC-Networks'!E6 -> 0.09990908 | E5: ='Appendix_BC-Networks'!D6 -> 6813 | F5: ='Table6 - Emissions'!F3 -> 384.64973 | H5: =($E5*$F5*'Table5 - Calculated values'!$D$3)/10^6 -> 6832854.1 | I5: =$H5/$H$20 -> 0.097626148 | L5: =D5/I5 -> 1.0233844
B6: FRA | C6: France | D6: ='Appendix_BC-Networks'!E7 -> 0.034212224 | E6: ='Appendix_BC-Networks'!D7 -> 2333 | F6: ='Table6 - Emissions'!I6 -> 57.184045 | H6: =($E6*$F6*'Table5 - Calculated values'!$D$3)/10^6 -> 347846.74 | I6: =$H6/$H$20 -> 0.0049699492 | L6: =D6/I6 -> 6.8838177
B7: CAN | C7: Canada | D7: ='Appendix_BC-Networks'!E8 -> 0.033303027 | E7: ='Appendix_BC-Networks'!D8 -> 2271 | F7: ='Table6 - Emissions'!I3 -> 142.99995 | H7: =($E7*$F7*'Table5 - Calculated values'!$D$3)/10^6 -> 846742.48 | I7: =$H7/$H$20 -> 0.012098049 | L7: =D7/I7 -> 2.75276
B8: GBR | C8: United Kingdom | D8: ='Appendix_BC-Networks'!E9 -> 0.025970788 | E8: ='Appendix_BC-Networks'!D9 -> 1771 | F8: ='Table6 - Emissions'!F8 -> 221.80271 | H8: =($E8*$F8*'Table5 - Calculated values'!$D$3)/10^6 -> 1024197.6 | I8: =$H8/$H$20 -> 0.014633484 | L8: =D8/I8 -> 1.7747508
B9: NLD | C9: Netherlands | D9: ='Appendix_BC-Networks'!E10 -> 0.025076255 | E9: ='Appendix_BC-Networks'!D10 -> 1710 | F9: ='Table6 - Emissions'!F7 -> 313.00492 | H9: =($E9*$F9*'Table5 - Calculated values'!$D$3)/10^6 -> 1395550.7 | I9: =$H9/$H$20 -> 0.019939286 | L9: =D9/I9 -> 1.2576305
B10: CHN | C10: China | D10: ='Appendix_BC-Networks'!E11 -> 0.021278156 | E10: ='Appendix_BC-Networks'!D11 -> 1451 | F10: ='Table6 - Emissions'!C5 -> 621.40188 | H10: =($E10*$F10*'Table5 - Calculated values'!$D$3)/10^6 -> 2350922.4 | I10: =$H10/$H$20 -> 0.033589405 | L10: =D10/I10 -> 0.6334782
B11: AUS | C11: Australia | D11: ='Appendix_BC-Networks'!E12 -> 0.019899695 | E11: ='Appendix_BC-Networks'!D12 -> 1357 | F11: ='Table6 - Emissions'!C6 -> 566.70679 | H11: =($E11*$F11*'Table5 - Calculated values'!$D$3)/10^6 -> 2005102.6 | I11: =$H11/$H$20 -> 0.028648415 | L11: =D11/I11 -> 0.69461766
B12: CHE | C12: Switzerland | D12: ='Appendix_BC-Networks'!E13 -> 0.017670695 | E12: ='Appendix_BC-Networks'!D13 -> 1205 | F12: ='Table6 - Emissions'!I7 -> 43.228378 | H12: =($E12*$F12*'Table5 - Calculated values'!$D$3)/10^6 -> 135817.06 | I12: =$H12/$H$20 -> 0.0019405209 | L12: =D12/I12 -> 9.1061603
B13: ESP | C13: Spain | D13: ='Appendix_BC-Networks'!E14 -> 0.016790826 | E13: ='Appendix_BC-Networks'!D14 -> 1145 | F13: ='Table6 - Emissions'!I2 -> 160.03648 | H13: =($E13*$F13*'Table5 - Calculated values'!$D$3)/10^6 -> 477774.33 | I13: =$H13/$H$20 -> 0.0068263228 | L13: =D13/I13 -> 2.4597175
B14: ITA | C14: Italy | D14: ='Appendix_BC-Networks'!E15 -> 0.01611626 | E14: ='Appendix_BC-Networks'!D15 -> 1099 | F14: ='Table6 - Emissions'!F5 -> 346.27211 | H14: =($E14*$F14*'Table5 - Calculated values'!$D$3)/10^6 -> 992232.7 | I14: =$H14/$H$20 -> 0.014176778 | L14: =D14/I14 -> 1.136807
B15: RUS | C15: Russia | D15: ='Appendix_BC-Networks'!E16 -> 0.01598428 | E15: ='Appendix_BC-Networks'!D16 -> 1090 | F15: ='Table6 - Emissions'!C9 -> 448.47052 | H15: =($E15*$F15*'Table5 - Calculated values'!$D$3)/10^6 -> 1274555.4 | I15: =$H15/$H$20 -> 0.018210536 | L15: =D15/I15 -> 0.87774898
B16: BRA | C16: Brazil | D16: ='Appendix_BC-Networks'!E17 -> 0.013579305 | E16: ='Appendix_BC-Networks'!D17 -> 926 | F16: ='Table6 - Emissions'!I5 -> 80.782081 | H16: =($E16*$F16*'Table5 - Calculated values'!$D$3)/10^6 -> 195040.3 | I16: =$H16/$H$20 -> 0.0027866881 | L16: =D16/I16 -> 4.8729191
B17: FIN | C17: Finland | D17: ='Appendix_BC-Networks'!E18 -> 0.012948733 | E17: ='Appendix_BC-Networks'!D18 -> 883 | F17: ='Table6 - Emissions'!I4 -> 88.338273 | H17: =($E17*$F17*'Table5 - Calculated values'!$D$3)/10^6 -> 203379.86 | I17: =$H17/$H$20 -> 0.0029058417 | L17: =D17/I17 -> 4.4561041
B18: JPN | C18: Japan | D18: ='Appendix_BC-Networks'!E19 -> 0.010118489 | E18: ='Appendix_BC-Networks'!D19 -> 690 | F18: ='Table6 - Emissions'!C8 -> 467.46655 | H18: =($E18*$F18*'Table5 - Calculated values'!$D$3)/10^6 -> 841003.8 | I18: =$H18/$H$20 -> 0.012016057 | L18: =D18/I18 -> 0.84208067
C19: Other | D19: =D20-SUM(D4:D18) -> 0.40614735 | E19: =$E$20-SUM(E4:E18) -> 27696 | F19: ='Table6 - Emissions'!I10 -> 481 | H19: =($E19*$F19*'Table5 - Calculated values'!$D$3)/10^6 -> 34734452 | I19: =$H19/$H$20 -> 0.49627736 | L19: =D19/I19 -> 0.81838783
C20: Total | D20: 1 | E20: ='Appendix_BC-Networks'!D31 -> 68192 | H20: ='Table4 - Overview of systems'!D3 -> 69990000 | I20: =$H20/$H$20 -> 1

Sheet Table8 - Ethereum
A2: Ethereum | B2: Top 15 Country | D2: Nodes | F2: Average Emissions per Energy by Country | H2: Total network energy consumption (09.11.25) | K2: CO2e Emissions per transaction [gCO2e/tx]
B3: [Distribution of Nodes] | D3: % | E3: Absolute | F3: [gCO2e / kWh] | H3: By Country [t] | I3: % | K3: Average for the network | L3: Factor > 1 = good to notarize; Factor < 1 = bad to notarize
B4: USA | C4: USA | D4: ='Appendix_BC-Networks'!K5 -> 0.31615044 | E4: 2858 | F4: ='Table6 - Emissions'!F4 -> 371.79463 | H4: =($E4*$F4*'Table5 - Calculated values'!$D$4)/10^6 -> 505.23171 | I4: =$H4/$H$20 -> 0.3846776 | K4: =$H$20*10^6/'Table4 - Overview of systems'!$C$4 -> 2.4674818 | L4: =D4/I4 -> 0.82185821
B5: GER | C5: Germany | D5: ='Appendix_BC-Networks'!K6 -> 0.14966814 | E5: 1353 | F5: ='Table6 - Emissions'!F3 -> 384.64973 | H5: =($E5*$F5*'Table5 - Calculated values'!$D$4)/10^6 -> 247.45059 | I5: =$H5/$H$20 -> 0.18840602 | L5: =D5/I5 -> 0.79439149
B6: FIN | C6: Finland | D6: ='Appendix_BC-Networks'!K7 -> 0.061061947 | E6: 552 | F6: ='Table6 - Emissions'!I4 -> 88.338273 | H6: =($E6*$F6*'Table5 - Calculated values'!$D$4)/10^6 -> 23.185328 | I6: =$H6/$H$20 -> 0.017653041 | L6: =D6/I6 -> 3.4590043
B7: FRA | C7: France | D7: ='Appendix_BC-Networks'!K8 -> 0.058738938 | E7: 531 | F7: ='Table6 - Emissions'!I6 -> 57.184045 | H7: =($E7*$F7*'Table5 - Calculated values'!$D$4)/10^6 -> 14.437588 | I7: =$H7/$H$20 -> 0.010992613 | L7: =D7/I7 -> 5.3434917
B8: GBR | C8: United Kingdom | D8: ='Appendix_BC-Networks'!K9 -> 0.041814159 | E8: 378 | F8: ='Table6 - Emissions'!F8 -> 221.80271 | H8: =($E8*$F8*'Table5 - Calculated values'!$D$4)/10^6 -> 39.864278 | I8: =$H8/$H$20 -> 0.030352202 | L8: =D8/I8 -> 1.3776318
B9: SGP | C9: Singapore | D9: ='Appendix_BC-Networks'!K10 -> 0.038606195 | E9: 349 | F9: ='Table6 - Emissions'!C7 -> 486.83131 | H9: =($E9*$F9*'Table5 - Calculated values'!$D$4)/10^6 -> 80.784713 | I9: =$H9/$H$20 -> 0.061508549 | L9: =D9/I9 -> 0.62765575
B10: CAN | C10: Canada | D10: ='Appendix_BC-Networks'!K11 -> 0.034845133 | E10: 315 | F10: ='Table6 - Emissions'!I3 -> 142.99995 | H10: =($E10*$F10*'Table5 - Calculated values'!$D$4)/10^6 -> 21.417644 | I10: =$H10/$H$20 -> 0.016307147 | L10: =D10/I10 -> 2.1368012
B11: NLD | C11: Netherlands | D11: ='Appendix_BC-Networks'!K12 -> 0.028429204 | E11: 257 | F11: ='Table6 - Emissions'!F7 -> 313.00492 | H11: =($E11*$F11*'Table5 - Calculated values'!$D$4)/10^6 -> 38.248072 | I11: =$H11/$H$20 -> 0.029121641 | L11: =D11/I11 -> 0.97622258
B12: JPN | C12: Japan | D12: ='Appendix_BC-Networks'!K13 -> 0.028097345 | E12: 254 | F12: ='Table6 - Emissions'!C8 -> 467.46655 | H12: =($E12*$F12*'Table5 - Calculated values'!$D$4)/10^6 -> 56.455924 | I12: =$H12/$H$20 -> 0.042984889 | L12: =D12/I12 -> 0.65365633
B13: KOR | C13: South Korea | D13: ='Appendix_BC-Networks'!K14 -> 0.023561947 | E13: 213 | F13: ='Table6 - Emissions'!C10 -> 439.51702 | H13: =($E13*$F13*'Table5 - Calculated values'!$D$4)/10^6 -> 44.512354 | I13: =$H13/$H$20 -> 0.033891193 | L13: =D13/I13 -> 0.6952233
B14: IRL | C14: Ireland | D14: ='Appendix_BC-Networks'!K15 -> 0.021128319 | E14: 191 | F14: ='Table6 - Emissions'!F6 -> 338.04433 | H14: =($E14*$F14*'Table5 - Calculated values'!$D$4)/10^6 -> 30.69957 | I14: =$H14/$H$20 -> 0.023374299 | L14: =D14/I14 -> 0.90391241
B15: AUT | C15: Austria | D15: ='Appendix_BC-Networks'!K16 -> 0.019247788 | E15: 174 | F15: ='Table6 - Emissions'!F10 -> 165.778 | H15: =($E15*$F15*'Table5 - Calculated values'!$D$4)/10^6 -> 13.715176 | I15: =$H15/$H$20 -> 0.010442577 | L15: =D15/I15 -> 1.8432028
B16: CHE | C16: Switzerland | D16: ='Appendix_BC-Networks'!K17 -> 0.017699115 | E16: 160 | F16: ='Table6 - Emissions'!I7 -> 43.228378 | H16: =($E16*$F16*'Table5 - Calculated values'!$D$4)/10^6 -> 3.2886237 | I16: =$H16/$H$20 -> 0.0025039202 | L16: =D16/I16 -> 7.068562
B17: CHN | C17: China | D17: ='Appendix_BC-Networks'!K18 -> 0.011283186 | E17: 102 | F17: ='Table6 - Emissions'!C5 -> 621.40188 | H17: =($E17*$F17*'Table5 - Calculated values'!$D$4)/10^6 -> 30.13686 | I17: =$H17/$H$20 -> 0.022945857 | L17: =D17/I17 -> 0.49173084
B18: POL | C18: Poland | D18: ='Appendix_BC-Networks'!K19 -> 0.010951327 | E18: 99 | F18: ='Table6 - Emissions'!C3 -> 698.98001 | H18: =($E18*$F18*'Table5 - Calculated values'!$D$4)/10^6 -> 32.902221 | I18: =$H18/$H$20 -> 0.025051372 | L18: =D18/I18 -> 0.4371548
C19: Other | D19: =D20-SUM(D4:D18) -> 0.13871681 | E19: =$E$20-SUM(E4:E18) -> 1254 | F19: ='Table6 - Emissions'!I10 -> 481 | H19: =($E19*$F19*'Table5 - Calculated values'!$D$4)/10^6 -> 286.79256 | I19: =$H19/$H$20 -> 0.21836055 | L19: =D19/I19 -> 0.63526501
C20: Total | D20: 1 | E20: ='Appendix_BC-Networks'!J31 -> 9040 | H20: ='Table4 - Overview of systems'!D4 -> 1313.39 | I20: =$H20/$H$20 -> 1

Sheet Table9 - Cardano
A2: Cardano | B2: Top 15 Country | D2: Nodes | F2: Average Emissions per Energy by Country | H2: Total network energy consumption (09.11.25) | K2: CO2e Emissions per transaction [gCO2e/tx]
B3: [Distribution of Nodes] | D3: % | E3: Absolute | F3: [gCO2e / kWh] | H3: By Country [t] | I3: % | K3: Average for the network | L3: Factor > 1 = good to notarize; Factor < 1 = bad to notarize
B4: GER | C4: Germany | D4: ='Appendix_BC-Networks'!Q5 -> 0.27440725 | E4: 787 | F4: ='Table6 - Emissions'!F3 -> 384.64973 | H4: =($E4*$F4*'Table5 - Calculated values'!$D$5)/10^6 -> 46.11509 | I4: =$H4/$H$20 -> 0.30768008 | K4: =$H$20*10^6/'Table4 - Overview of systems'!$C$5 -> 5.3147061 | L4: =D4/I4 -> 0.89185902
B5: USA | C5: USA | D5: ='Appendix_BC-Networks'!Q6 -> 0.25906555 | E5: 743 | F5: ='Table6 - Emissions'!F4 -> 371.79463 | H5: =($E5*$F5*'Table5 - Calculated values'!$D$5)/10^6 -> 42.08185 | I5: =$H5/$H$20 -> 0.28077028 | L5: =D5/I5 -> 0.92269576
B6: GBR | C6: United Kingdom | D6: ='Appendix_BC-Networks'!Q7 -> 0.060669456 | E6: 174 | F6: ='Table6 - Emissions'!F8 -> 221.80271 | H6: =($E6*$F6*'Table5 - Calculated values'!$D$5)/10^6 -> 5.8792102 | I6: =$H6/$H$20 -> 0.039226116 | L6: =D6/I6 -> 1.5466598
B7: NLD | C7: Netherlands | D7: ='Appendix_BC-Networks'!Q8 -> 0.049511855 | E7: 142 | F7: ='Table6 - Emissions'!F7 -> 313.00492 | H7: =($E7*$F7*'Table5 - Calculated values'!$D$5)/10^6 -> 6.7708378 | I7: =$H7/$H$20 -> 0.045175058 | L7: =D7/I7 -> 1.0959998
B8: FRA | C8: France | D8: ='Appendix_BC-Networks'!Q9 -> 0.039400279 | E8: 113 | F8: ='Table6 - Emissions'!I6 -> 57.184045 | H8: =($E8*$F8*'Table5 - Calculated values'!$D$5)/10^6 -> 0.98436512 | I8: =$H8/$H$20 -> 0.0065676883 | L8: =D8/I8 -> 5.9991092
B9: JPN | C9: Japan | D9: ='Appendix_BC-Networks'!Q10 -> 0.04567643 | E9: 131 | F9: ='Table6 - Emissions'!C8 -> 467.46655 | H9: =($E9*$F9*'Table5 - Calculated values'!$D$5)/10^6 -> 9.3287774 | I9: =$H9/$H$20 -> 0.062241643 | L9: =D9/I9 -> 0.73385642
B10: CAN | C10: Canada | D10: ='Appendix_BC-Networks'!Q11 -> 0.053695955 | E10: 154 | F10: ='Table6 - Emissions'!I3 -> 142.99995 | H10: =($E10*$F10*'Table5 - Calculated values'!$D$5)/10^6 -> 3.3547449 | I10: =$H10/$H$20 -> 0.022382872 | L10: =D10/I10 -> 2.3989752
B11: SWE | C11: Sweden | D11: ='Appendix_BC-Networks'!Q12 -> 0.013249651 | E11: 38 | F11: ='Table6 - Emissions'!I8 -> 25.64434 | H11: =($E11*$F11*'Table5 - Calculated values'!$D$5)/10^6 -> 0.14844925 | I11: =$H11/$H$20 -> 0.00099045404 | L11: =D11/I11 -> 13.377351
B12: FIN | C12: Finland | D12: ='Appendix_BC-Networks'!Q13 -> 0.035216179 | E12: 101 | F12: ='Table6 - Emissions'!I4 -> 88.338273 | H12: =($E12*$F12*'Table5 - Calculated values'!$D$5)/10^6 -> 1.3591681 | I12: =$H12/$H$20 -> 0.0090683755 | L12: =D12/I12 -> 3.8834054
B13: IRL | C13: Ireland | D13: ='Appendix_BC-Networks'!Q14 -> 0.012900976 | E13: 37 | F13: ='Table6 - Emissions'!F6 -> 338.04433 | H13: =($E13*$F13*'Table5 - Calculated values'!$D$5)/10^6 -> 1.9053654 | I13: =$H13/$H$20 -> 0.012712606 | L13: =D13/I13 -> 1.0148176
B14: KOR | C14: South Korea | D14: ='Appendix_BC-Networks'!Q15 -> 0.018479777 | E14: 53 | F14: ='Table6 - Emissions'!C10 -> 439.51702 | H14: =($E14*$F14*'Table5 - Calculated values'!$D$5)/10^6 -> 3.5485789 | I14: =$H14/$H$20 -> 0.023676133 | L14: =D14/I14 -> 0.78052343
B15: AUS | C15: Australia | D15: ='Appendix_BC-Networks'!Q16 -> 0.017433752 | E15: 50 | F15: ='Table6 - Emissions'!C6 -> 566.70679 | H15: =($E15*$F15*'Table5 - Calculated values'!$D$5)/10^6 -> 4.3164958 | I15: =$H15/$H$20 -> 0.028799678 | L15: =D15/I15 -> 0.60534537
B16: IND | C16: India | D16: ='Appendix_BC-Networks'!Q17 -> 0.010808926 | E16: 31 | F16: ='Table6 - Emissions'!C2 -> 774.59956 | H16: =($E16*$F16*'Table5 - Calculated values'!$D$5)/10^6 -> 3.6579843 | I16: =$H16/$H$20 -> 0.024406087 | L16: =D16/I16 -> 0.44287829
B17: SGP | C17: Singapore | D17: ='Appendix_BC-Networks'!Q18 -> 0.021617852 | E17: 62 | F17: ='Table6 - Emissions'!C7 -> 486.83131 | H17: =($E17*$F17*'Table5 - Calculated values'!$D$5)/10^6 -> 4.5980436 | I17: =$H17/$H$20 -> 0.030678167 | L17: =D17/I17 -> 0.70466571
B18: AUT | C18: Austria | D18: ='Appendix_BC-Networks'!Q19 -> 0.0090655509 | E18: 26 | F18: ='Table6 - Emissions'!F10 -> 165.778 | H18: =($E18*$F18*'Table5 - Calculated values'!$D$5)/10^6 -> 0.65660341 | I18: =$H18/$H$20 -> 0.0043808607 | L18: =D18/I18 -> 2.0693538
C19: Other | D19: =D20-SUM(D4:D18) -> 0.078800558 | E19: =$E$20-SUM(E4:E18) -> 226 | F19: ='Table6 - Emissions'!I10 -> 481 | H19: =($E19*$F19*'Table5 - Calculated values'!$D$5)/10^6 -> 16.559851 | I19: =$H19/$H$20 -> 0.11048739 | L19: =D19/I19 -> 0.71320859
C20: Total | D20: 1 | E20: ='Appendix_BC-Networks'!P58 -> 2868 | H20: ='Table4 - Overview of systems'!D5 -> 149.88 | I20: =$H20/$H$20 -> 1

Sheet Table10 - Solana
A2: Solana | B2: Top 15 Country | D2: Nodes | F2: Average Emissions per Energy by Country | H2: Total network energy consumption (09.11.25) | K2: CO2e Emissions per transaction [gCO2e/tx]
B3: [Distribution of Nodes] | D3: % | E3: Absolute | F3: [gCO2e / kWh] | H3: By Country [t] | I3: % | K3: Average for the network | L3: Factor > 1 = good to notarize; Factor < 1 = bad to notarize
B4: USA | C4: USA | D4: ='Appendix_BC-Networks'!W5 -> 0.30547009 | E4: 787 | F4: ='Table6 - Emissions'!F4 -> 371.79463 | H4: =($E4*$F4*'Table5 - Calculated values'!$D$6)/10^6 -> 825.87696 | I4: =$H4/$H$20 -> 0.16273309 | K4: =$H$20*10^6/'Table4 - Overview of systems'!$C$6 -> 0.055457485 | L4: =D4/I4 -> 1.8771233
B5: GER | C5: Germany | D5: ='Appendix_BC-Networks'!W6 -> 0.2 | E5: 743 | F5: ='Table6 - Emissions'!F3 -> 384.64973 | H5: =($E5*$F5*'Table5 - Calculated values'!$D$6)/10^6 -> 806.66227 | I5: =$H5/$H$20 -> 0.15894698 | L5: =D5/I5 -> 1.2582812
B6: NLD | C6: Netherlands | D6: ='Appendix_BC-Networks'!W7 -> 0.12102564 | E6: 174 | F6: ='Table6 - Emissions'!F7 -> 313.00492 | H6: =($E6*$F6*'Table5 - Calculated values'!$D$6)/10^6 -> 153.72267 | I6: =$H6/$H$20 -> 0.030289942 | L6: =D6/I6 -> 3.9955719
B7: FRA | C7: France | D7: ='Appendix_BC-Networks'!W8 -> 0.058290598 | E7: 142 | F7: ='Table6 - Emissions'!I6 -> 57.184045 | H7: =($E7*$F7*'Table5 - Calculated values'!$D$6)/10^6 -> 22.919267 | I7: =$H7/$H$20 -> 0.0045160761 | L7: =D7/I7 -> 12.907355
B8: CAN | C8: Canada | D8: ='Appendix_BC-Networks'!W9 -> 0.057777778 | E8: 113 | F8: ='Table6 - Emissions'!I3 -> 142.99995 | H8: =($E8*$F8*'Table5 - Calculated values'!$D$6)/10^6 -> 45.609134 | I8: =$H8/$H$20 -> 0.0089869507 | L8: =D8/I8 -> 6.4290747
B9: JPN | C9: Japan | D9: ='Appendix_BC-Networks'!W10 -> 0.053333333 | E9: 131 | F9: ='Table6 - Emissions'!C8 -> 467.46655 | H9: =($E9*$F9*'Table5 - Calculated values'!$D$6)/10^6 -> 172.846 | I9: =$H9/$H$20 -> 0.034058057 | L9: =D9/I9 -> 1.5659535
B10: SGP | C10: Singapore | D10: ='Appendix_BC-Networks'!W11 -> 0.040854701 | E10: 154 | F10: ='Table6 - Emissions'!C7 -> 486.83131 | H10: =($E10*$F10*'Table5 - Calculated values'!$D$6)/10^6 -> 211.61026 | I10: =$H10/$H$20 -> 0.041696274 | L10: =D10/I10 -> 0.97981658
B11: GBR | C11: United Kingdom | D11: ='Appendix_BC-Networks'!W12 -> 0.040683761 | E11: 38 | F11: ='Table6 - Emissions'!F8 -> 221.80271 | H11: =($E11*$F11*'Table5 - Calculated values'!$D$6)/10^6 -> 23.789644 | I11: =$H11/$H$20 -> 0.0046875776 | L11: =D11/I11 -> 8.6790585
B12: LTU | C12: Lithunia | D12: ='Appendix_BC-Networks'!W13 -> 0.011282051 | E12: 101 | F12: ='Table6 - Emissions'!F9 -> 169.75148 | H12: =($E12*$F12*'Table5 - Calculated values'!$D$6)/10^6 -> 48.391875 | I12: =$H12/$H$20 -> 0.0095352696 | L12: =D12/I12 -> 1.1831916
B13: IRL | C13: Ireland | D13: ='Appendix_BC-Networks'!W14 -> 0.011111111 | E13: 37 | F13: ='Table6 - Emissions'!F6 -> 338.04433 | H13: =($E13*$F13*'Table5 - Calculated values'!$D$6)/10^6 -> 35.303104 | I13: =$H13/$H$20 -> 0.0069562218 | L13: =D13/I13 -> 1.5972911
B14: RUS | C14: Russia | D14: ='Appendix_BC-Networks'!W15 -> 0.0073504274 | E14: 53 | F14: ='Table6 - Emissions'!C9 -> 448.47052 | H14: =($E14*$F14*'Table5 - Calculated values'!$D$6)/10^6 -> 67.088375 | I14: =$H14/$H$20 -> 0.01321928 | L14: =D14/I14 -> 0.5560384
B15: NOR | C15: Norway | D15: ='Appendix_BC-Networks'!W16 -> 0.0061538462 | E15: 50 | F15: ='Table6 - Emissions'!I9 -> 22.945155 | H15: =($E15*$F15*'Table5 - Calculated values'!$D$6)/10^6 -> 3.2381615 | I15: =$H15/$H$20 -> 0.00063805635 | L15: =D15/I15 -> 9.644675
B16: POL | C16: Poland | D16: ='Appendix_BC-Networks'!W17 -> 0.0056410256 | E16: 31 | F16: ='Table6 - Emissions'!C3 -> 698.98001 | H16: =($E16*$F16*'Table5 - Calculated values'!$D$6)/10^6 -> 61.159504 | I16: =$H16/$H$20 -> 0.012051039 | L16: =D16/I16 -> 0.46809456
B17: HKG | C17: Hong Kong | D17: ='Appendix_BC-Networks'!W18 -> 0.0052991453 | E17: 62 | F17: ='Table6 - Emissions'!C4 -> 695.96903 | H17: =($E17*$F17*'Table5 - Calculated values'!$D$6)/10^6 -> 121.7921 | I17: =$H17/$H$20 -> 0.023998254 | L17: =D17/I17 -> 0.22081379
B18: SWE | C18: Sweden | D18: ='Appendix_BC-Networks'!W19 -> 0.0051282051 | E18: 26 | F18: ='Table6 - Emissions'!I8 -> 25.64434 | H18: =($E18*$F18*'Table5 - Calculated values'!$D$6)/10^6 -> 1.8819252 | I18: =$H18/$H$20 -> 0.00037081979 | L18: =D18/I18 -> 13.829373
C19: Other | D19: =D20-SUM(D4:D18) -> 0.070598291 | E19: =$E$20-SUM(E4:E18) -> 3208 | F19: ='Table6 - Emissions'!I10 -> 481 | H19: =($E19*$F19*'Table5 - Calculated values'!$D$5)/10^6 -> 235.06195 | I19: =$H19/$H$20 -> 0.04631726 | L19: =D19/I19 -> 1.5242329
C20: Total | D20: 1 | E20: ='Appendix_BC-Networks'!V31 -> 5850 | H20: ='Table4 - Overview of systems'!D6 -> 5075.04 | I20: =$H20/$H$20 -> 1

Sheet Table11 - Ripple
A2: Ripple (XRP) | B2: Top 15 Country | D2: Nodes | F2: Average Emissions per Energy by Country | H2: Total network energy consumption (09.11.25) | K2: CO2e Emissions per transaction [gCO2e/tx]
B3: [Distribution of Nodes] | D3: % | E3: Absolute | F3: [gCO2e / kWh] | H3: By Country [t] | I3: % | K3: Average for the network | L3: Factor > 1 = good to notarize; Factor < 1 = bad to notarize
B4: USA | C4: USA | D4: ='Appendix_BC-Networks'!AC5 -> 0.21822272 | E4: 194 | F4: ='Table6 - Emissions'!F4 -> 371.79463 | H4: =($E4*$F4*'Table5 - Calculated values'!$D$7)/10^6 -> 38.276604 | I4: =$H4/$H$20 -> 0.19711919 | K4: =$H$20*10^6/'Table4 - Overview of systems'!$C$7 -> 0.49737104 | L4: =(D4/I4) -> 1.1070598
B5: GER | C5: Germany | D5: ='Appendix_BC-Networks'!AC6 -> 0.11811024 | E5: 105 | F5: ='Table6 - Emissions'!F3 -> 384.64973 | H5: =($E5*$F5*'Table5 - Calculated values'!$D$7)/10^6 -> 21.433016 | I5: =$H5/$H$20 -> 0.11037705 | L5: =(D5/I5) -> 1.0700615
B6: FIN | C6: Finland | D6: ='Appendix_BC-Networks'!AC7 -> 0.070866142 | E6: 63 | F6: ='Table6 - Emissions'!I4 -> 88.338273 | H6: =($E6*$F6*'Table5 - Calculated values'!$D$7)/10^6 -> 2.9533711 | I6: =$H6/$H$20 -> 0.01520945 | L6: =(D6/I6) -> 4.6593493
B7: JPN | C7: Japan | D7: ='Appendix_BC-Networks'!AC8 -> 0.052868391 | E7: 47 | F7: ='Table6 - Emissions'!C8 -> 467.46655 | H7: =($E7*$F7*'Table5 - Calculated values'!$D$7)/10^6 -> 11.65942 | I7: =$H7/$H$20 -> 0.060044393 | L7: =(D7/I7) -> 0.8804884
B8: SGP | C8: Singapore | D8: ='Appendix_BC-Networks'!AC9 -> 0.046119235 | E8: 41 | F8: ='Table6 - Emissions'!C7 -> 486.83131 | H8: =($E8*$F8*'Table5 - Calculated values'!$D$7)/10^6 -> 10.592316 | I8: =$H8/$H$20 -> 0.054548953 | L8: =(D8/I8) -> 0.84546508
B9: NLD | C9: Netherlands | D9: ='Appendix_BC-Networks'!AC10 -> 0.038245219 | E9: 34 | F9: ='Table6 - Emissions'!F7 -> 313.00492 | H9: =($E9*$F9*'Table5 - Calculated values'!$D$7)/10^6 -> 5.6475312 | I9: =$H9/$H$20 -> 0.029084001 | L9: =(D9/I9) -> 1.3149917
B10: FRA | C10: France | D10: ='Appendix_BC-Networks'!AC11 -> 0.035995501 | E10: 32 | F10: ='Table6 - Emissions'!I6 -> 57.184045 | H10: =($E10*$F10*'Table5 - Calculated values'!$D$7)/10^6 -> 0.97107643 | I10: =$H10/$H$20 -> 0.0050009086 | L10: =(D10/I10) -> 7.1977921
B11: KOR | C11: South Korea | D11: ='Appendix_BC-Networks'!AC12 -> 0.028121485 | E11: 25 | F11: ='Table6 - Emissions'!C10 -> 439.51702 | H11: =($E11*$F11*'Table5 - Calculated values'!$D$7)/10^6 -> 5.8310164 | I11: =$H11/$H$20 -> 0.030028924 | L11: =(D11/I11) -> 0.93647994
B12: IRL | C12: Ireland | D12: ='Appendix_BC-Networks'!AC13 -> 0.028121485 | E12: 25 | F12: ='Table6 - Emissions'!F6 -> 338.04433 | H12: =($E12*$F12*'Table5 - Calculated values'!$D$7)/10^6 -> 4.4847912 | I12: =$H12/$H$20 -> 0.023096051 | L12: =(D12/I12) -> 1.2175884
B13: GBR | C13: United Kingdom | D13: ='Appendix_BC-Networks'!AC14 -> 0.025871766 | E13: 23 | F13: ='Table6 - Emissions'!F8 -> 221.80271 | H13: =($E13*$F13*'Table5 - Calculated values'!$D$7)/10^6 -> 2.7072181 | I13: =$H13/$H$20 -> 0.013941797 | L13: =(D13/I13) -> 1.8556981
B14: CAN | C14: Canada | D14: ='Appendix_BC-Networks'!AC15 -> 0.022497188 | E14: 20 | F14: ='Table6 - Emissions'!I3 -> 142.99995 | H14: =($E14*$F14*'Table5 - Calculated values'!$D$7)/10^6 -> 1.5177297 | I14: =$H14/$H$20 -> 0.0078160971 | L14: =(D14/I14) -> 2.8783148
B15: EST | C15: Estonia | D15: ='Appendix_BC-Networks'!AC16 -> 0.012373453 | E15: 11 | F15: ='Table6 - Emissions'!F2 -> 433.8617 | H15: =($E15*$F15*'Table5 - Calculated values'!$D$7)/10^6 -> 2.5326348 | I15: =$H15/$H$20 -> 0.013042717 | L15: =(D15/I15) -> 0.9486868
B16: AUS | C16: Australia | D16: ='Appendix_BC-Networks'!AC17 -> 0.012373453 | E16: 11 | F16: ='Table6 - Emissions'!C6 -> 566.70679 | H16: =($E16*$F16*'Table5 - Calculated values'!$D$7)/10^6 -> 3.3081079 | I16: =$H16/$H$20 -> 0.017036296 | L16: =(D16/I16) -> 0.72629952
B17: HKG | C17: Hong Kong | D17: ='Appendix_BC-Networks'!AC18 -> 0.011248594 | E17: 10 | F17: ='Table6 - Emissions'!C4 -> 695.96903 | H17: =($E17*$F17*'Table5 - Calculated values'!$D$7)/10^6 -> 3.6933331 | I17: =$H17/$H$20 -> 0.019020152 | L17: =(D17/I17) -> 0.591404
B18: CHE | C18: Switzerland | D18: ='Appendix_BC-Networks'!AC19 -> 0.0089988751 | E18: 8 | F18: ='Table6 - Emissions'!I7 -> 43.228378 | H18: =($E18*$F18*'Table5 - Calculated values'!$D$7)/10^6 -> 0.18352173 | I18: =$H18/$H$20 -> 0.00094511138 | L18: =(D18/I18) -> 9.5214969
C19: Other | D19: =D20-SUM(D4:D18) -> 0.26996625 | E19: =$E$20-SUM(E4:E18) -> 240 | F19: ='Table6 - Emissions'!I10 -> 481 | H19: =($E19*$F19*'Table5 - Calculated values'!$D$7)/10^6 -> 61.261112 | I19: =$H19/$H$20 -> 0.31548621 | L19: =(D19/I19) -> 0.85571491
C20: Total | D20: 1 | E20: ='Appendix_BC-Networks'!AB31 -> 889 | H20: ='Table4 - Overview of systems'!D7 -> 194.18 | I20: =$H20/$H$20 -> 1

Sheet Table12
B1: x = 6 | C1: Energy Consumption (x) | D1: Emissions (x) | E1: Price (x)
B2: System | C2: kWh / t(x) | D2: kgCO2e / t(x) | E2: $ /t (x)
B3: Bitcoin | C3: ='Table5 - Calculated values'!B3*6 -> 6269.2023 | D3: ='Table4 - Overview of systems'!E3/1000*6 -> 2467.8373 | E3: ='Table5 - Calculated values'!F3*6 -> 6.072
B4: Ethereum | C4: ='Table5 - Calculated values'!B4*6 -> 0.048451274 | D4: ='Table4 - Overview of systems'!E4/1000*6 -> 0.014804891 | E4: ='Table5 - Calculated values'!F4*6 -> 3.354
B5: Cardano | C5: ='Table5 - Calculated values'!B5*6 -> 0.092954167 | D5: ='Table4 - Overview of systems'!E5/1000*6 -> 0.031888237 | E5: ='Table5 - Calculated values'!F5*6 -> 0.5713123
B6: Solana | C6: ='Table5 - Calculated values'!B6*6 -> 0.0010825933 | D6: ='Table5 - Calculated values'!E6/1000*6 -> 0.001933235 | E6: ='Table5 - Calculated values'!F6*6 -> 0.00915
B7: Ripple | C7: ='Table5 - Calculated values'!B7*6 -> 0.0072503266 | D7: ='Table4 - Overview of systems'!E7/1000*6 -> 0.0029842262 | E7: ='Table5 - Calculated values'!F7*6 -> 0.0051
B8: Iota | C8: undefined | D8: ='Table4 - Overview of systems'!E8/1000*6 -> 0.00048600732 | E8: 0

Sheet Table13
A1: Tree Species | B1: Sequestered kgCO2e/m³
A2: Fagus sylvatica | B2: 1063
A3: Quercus Robus | B3: 1063
A4: Pinus Sylvestris | B4: 823
A5: Pseudotsuga Menziesii | B5: 789
A6: Picea Abies | B6: 722

Sheet Table14
A1: System | B1: Energy Requirement in kWh/tx | C1: CO2 Emissions in gCO2e/tx | D1: Transaction Speed (TPS) | E1: Cost per Transaction in $/tx
A2: Bitcoin (PoW) | B2: Very High | C2: Very High | D2: Very Low | E2: Very High
B3: ='Table5 - Calculated values'!B3 -> 1044.867 | C3: ='Table4 - Overview of systems'!E3 -> 411306.21 | D3: 7 | E3: ='Table5 - Calculated values'!F3 -> 1.012
A4: Ethereum (PoS) | B4: Very Low | C4: Very Low | D4: Low | E4: Moderate
B5: ='Table5 - Calculated values'!B4 -> 0.0080752124 | C5: ='Table4 - Overview of systems'!E4 -> 2.4674818 | D5: 16.5 | E5: ='Table5 - Calculated values'!F4 -> 0.559
A6: Cardano (PoS) | B6: Low | C6: Very Low | D6: Very Low | E6: Low
B7: ='Table5 - Calculated values'!B5 -> 0.015492361 | C7: ='Table4 - Overview of systems'!E5 -> 5.3147061 | D7: 5.7 | E7: ='Table5 - Calculated values'!F5 -> 0.095218716
A8: Solana (PoH/PoS) | B8: Extremely Low | C8: Extremely Low | D8: Very High | E8: Extremely Low
B9: ='Table5 - Calculated values'!B6 -> 0.00018043221 | C9: ='Table4 - Overview of systems'!E6 -> 0.055457485 | D9: 50000 | E9: ='Table5 - Calculated values'!F6 -> 0.001525
A10: Ripple (PBFT) | B10: Extremely Low | C10: Extremely Low | D10: High | E10: Extremely Low
B11: ='Table5 - Calculated values'!B7 -> 0.0012083878 | C11: ='Table4 - Overview of systems'!E7 -> 0.49737104 | D11: 1500 | E11: ='Table5 - Calculated values'!F7 -> 0.00085
A12: IOTA (DAG) | B12: Extremely Low | C12: Extremely Low | D12: Extremely High | E12: No Costs
B13: ='Table5 - Calculated values'!B8 -> 0.00031242918 | C13: ='Table4 - Overview of systems'!E8 -> 0.081001219 | D13: 1000 - ∞ | E13: 0

Sheet CO2e  kWh per Country
A1: Carbon Footprint Ltd's Greenhouse Gas Emissions Factors for International Grid Electricity (calculated from fuel mix)
A2: Published by: Carbon Footprint Ltd
A3: Published date: 31 July 2024
A5: Methodology:
A6: The GHG emissions factor calculations provided in the table below are based on electricity fuel mix data from :
A7: Ember (2024); Energy Institute - Statistical Review of World Energy (2024) – with major processing by Our World in Data. “Total electricity generation – Ember and Energy Institute” [dataset]. Ember, “Yearly Electricity Data”; Energy Institute, “Statistical Review of World Energy” [original data].
A9: The calculations use GHG Conversion factors for fuels published by the UK Gov 2024 for Fuel emissions and Fuel Well to Tank (WTT) emissions
A10: Greenhouse gas reporting: conversion factors 2024 - GOV.UK (www.gov.uk)
A12: Power station efficiencies have been accounted for using : Energy Efficiency Indicators for Public Electricity Production from Fossil Fuels, IEA, July 2008
A13: Hydro, Solar, Wind and Nuclear energy are assumed to be zero emissions
A15: The Transmission & Distribution (T&D) Factor assumes the same percentage losses as in the past and uses ratios (Generation to T&D) calculated from the UK Gov 2015 factors, apart from the UK's T&D, which uses the ratio calculated from the most recent UK Gov 2024 factors release
A16: For countries where the T&D was not included in the DEFRA 2015 emissions factors, "world average" values have been applied.
A20: Source1 Carbon Footprint Ltd | K20: Source 3 Our World in Data 2023 (Last update 20.06.2024) | L20: Source4 ElectrcityMaps (Average Feb. 2024 - Jan. 2025) | M20: Source2 VDA 2020 (Last Update Sep. 2024)
F21: Scope 2 (2024) | G21: Scope 3 | H21: Scope 3 | I21: Scope 3 | J21: Scope 2 (2024)
A22: Country | B22: Country 3 Letter Code | C22: Country 2 Letter Code | D22: Factor Year | E22: Fuel Mix Data Year | F22: Electricity Generation Emissions Factor (kg CO2e/kWh) | G22: Estimated T&D Factor (kg CO2e/kWh) | H22: Estimated WTT Factor (kg CO2e/kWh) | I22: Estimated WTT of T&D Factor (kg CO2e/kWh) | J22: Electricity Generation Emissions Factor (g CO2e/kWh) | K22: g CO2e/kWh | L22: g CO2e/kWh | M22: g CO2e/kWh | O22: Priorität - Source4 - Source1 - Source3 - Source2* mit Vermerk
A23: Afghanistan | B23: AFG | C23: AF | D23: 2024 | E23: 2022 | F23: 0.12835126 | G23: 0.018849737 | H23: 0.026783909 | I23: 0.0039334998 | J23: =$F23*1000 -> 128.35126
A24: Albania | B24: ALB | C24: AL | D24: 2024 | E24: 2022 | F24: 0 | G24: 0 | H24: 0 | I24: 0 | J24: =$F24*1000 -> 0 | K24: 24 | L24: 113 | M24: n.A.
A25: Algeria | B25: DZA | C25: DZ | D25: 2024 | E25: 2022 | F25: 0.50817938 | G25: 0.076395432 | H25: 0.08340186 | I25: 0.012537937 | J25: =$F25*1000 -> 508.17938
A26: American Samoa | B26: ASM | C26: AS | D26: 2024 | E26: 2022 | F26: 0.72806453 | G26: 0.049962378 | H26: 0.16058107 | I26: 0.011019644 | J26: =$F26*1000 -> 728.06453
A27: Angola | B27: AGO | C27: AO | D27: 2024 | E27: 2022 | F27: 0.16696991 | G27: 0.025100858 | H27: 0.034259444 | I27: 0.005150278 | J27: =$F27*1000 -> 166.96991
A28: Antigua and Barbuda | B28: ATG | C28: AG | D28: 2024 | E28: 2022 | F28: 0.72806453 | G28: 0.13816706 | H28: 0.16058107 | I28: 0.030473968 | J28: =$F28*1000 -> 728.06453
A29: Argentina | B29: ARG | C29: AR | D29: 2024 | E29: 2022 | F29: 0.37617188 | G29: 0.071387303 | H29: 0.068439669 | I29: 0.012988008 | J29: =$F29*1000 -> 376.17188 | K29: 354 | L29: 433 | M29: 405
A30: Armenia | B30: ARM | C30: AM | D30: 2024 | E30: 2022 | F30: 0.22199656 | G30: 0.032602539 | H30: 0.036351394 | I30: 0.005338586 | J30: =$F30*1000 -> 221.99656
A31: Aruba | B31: ABW | C31: AW | D31: 2024 | E31: 2022 | F31: 0.65289825 | G31: 0.12390252 | H31: 0.14400249 | I31: 0.027327798 | J31: =$F31*1000 -> 652.89825
A32: Australia | B32: AUS | C32: AU | D32: 2024 | E32: 2022 | F32: 0.59512037 | G32: 0.035841812 | H32: 0.10632678 | I32: 0.0064036535 | J32: =$F32*1000 -> 595.12037 | K32: 549 | L32: 556 | M32: 842
A33: Austria | B33: AUT | C33: AT | D33: 2024 | E33: 2022 | F33: 0.11733399 | G33: 0.00691311 | H33: 0.028859376 | I33: 0.0017003432 | J33: =$F33*1000 -> 117.33399 | K33: 111 | L33: 269 | M33: 245
A34: Azerbaijan | B34: AZE | C34: AZ | D34: 2024 | E34: 2022 | F34: 0.4794307 | G34: 0.070409461 | H34: 0.078993135 | I34: 0.011600976 | J34: =$F34*1000 -> 479.4307
A35: Bahamas | B35: BHS | C35: BS | D35: 2024 | E35: 2022 | F35: 0.77089189 | G35: 0.14629454 | H35: 0.17002703 | I35: 0.032266556 | J35: =$F35*1000 -> 770.89189
A36: Bahrain | B36: BHR | C36: BH | D36: 2024 | E36: 2022 | F36: 0.5108562 | G36: 0.081033416 | H36: 0.083651454 | I36: 0.013269024 | J36: =$F36*1000 -> 510.8562
A37: Bangladesh | B37: BGD | C37: BD | D37: 2024 | E37: 2022 | F37: 0.59621142 | G37: 0.087559943 | H37: 0.10946377 | I37: 0.01607591 | J37: =$F37*1000 -> 596.21142
A38: Barbados | B38: BRB | C38: BB | D38: 2024 | E38: 2022 | F38: 0.70715971 | G38: 0.13419989 | H38: 0.15517132 | I38: 0.029447343 | J38: =$F38*1000 -> 707.15971
A39: Belarus | B39: BLR | C39: BY | D39: 2024 | E39: 2022 | F39: 0.44529651 | G39: 0.065396494 | H39: 0.076544341 | I39: 0.011241345 | J39: =$F39*1000 -> 445.29651
A40: Belgium | B40: BEL | C40: BE | D40: 2024 | E40: 2022 | F40: 0.1252452 | G40: 0.0063677278 | H40: 0.027533971 | I40: 0.0013998846 | J40: =$F40*1000 -> 125.2452 | K40: 138 | L40: 196 | M40: 179
A41: Belize | B41: BLZ | C41: BZ | D41: 2024 | E41: 2022 | F41: 0.16589798 | G41: 0.031482974 | H41: 0.08811952 | I41: 0.016722714 | J41: =$F41*1000 -> 165.89798
A42: Benin | B42: BEN | C42: BJ | D42: 2024 | E42: 2022 | F42: 0.55255417 | G42: 0.083066367 | H42: 0.099005925 | I42: 0.014883722 | J42: =$F42*1000 -> 552.55417
A43: Bermuda | B43: BMU | C43: BM | D43: 2024 | E43: 2022 | F43: 0.7591689 | G43: 0.091714884 | H43: 0.16902615 | I43: 0.02041998 | J43: =$F43*1000 -> 759.1689
A44: Bhutan | B44: BTN | C44: BT | D44: 2024 | E44: 2022 | F44: 0 | G44: 0 | H44: 0 | I44: 0 | J44: =$F44*1000 -> 0
A45: Bolivia | B45: BOL | C45: BO | D45: 2024 | E45: 2022 | F45: 0.33792103 | G45: 0.06412832 | H45: 0.059577914 | I45: 0.011306285 | J45: =$F45*1000 -> 337.92103 | K45: 532 | L45: 322 | M45: n.A.
A46: Bosnia and Herzegovina | B46: BIH | C46: BA | D46: 2024 | E46: 2022 | F46: 0.6525874 | G46: 0.095839351 | H46: 0.11618164 | I46: 0.0170625 | J46: =$F46*1000 -> 652.5874
A47: Botswana | B47: BWA | C47: BW | D47: 2024 | E47: 2022 | F47: 0.9696756 | G47: 0.14577291 | H47: 0.17344097 | I47: 0.026073664 | J47: =$F47*1000 -> 969.6756
...
